Workbook

Sheet Dashboard
B2: Dashboard — Indicadores por Instrutor
B4: Instrutor | C4: Qtde Treinamentos | D4: Custo Total (R$) | E4: Custo Médio por Treinamento (R$)
B5: Betânia Cayret Pregnolato | C5: =COUNTIF(Treinamentos_Feitos!$B$2:$B$2000,"*"&B5&"*") -> 86 | D5: =SUMIF(Treinamentos_Feitos!$B$2:$B$2000,"*"&B5&"*",Treinamentos_Feitos!$H$2:$H$2000) -> 43473.29 | E5: =IFERROR(D5/C5,0) -> 505.50337
B6: Bruno Souza | C6: =COUNTIF(Treinamentos_Feitos!$B$2:$B$2000,"*"&B6&"*") -> 106 | D6: =SUMIF(Treinamentos_Feitos!$B$2:$B$2000,"*"&B6&"*",Treinamentos_Feitos!$H$2:$H$2000) -> 54632.89 | E6: =IFERROR(D6/C6,0) -> 515.40462
B7: Carla Fernandes Dionizio | C7: =COUNTIF(Treinamentos_Feitos!$B$2:$B$2000,"*"&B7&"*") -> 61 | D7: =SUMIF(Treinamentos_Feitos!$B$2:$B$2000,"*"&B7&"*",Treinamentos_Feitos!$H$2:$H$2000) -> 30988.71 | E7: =IFERROR(D7/C7,0) -> 508.01164
B8: Isabela Paim Ricardo | C8: =COUNTIF(Treinamentos_Feitos!$B$2:$B$2000,"*"&B8&"*") -> 156 | D8: =SUMIF(Treinamentos_Feitos!$B$2:$B$2000,"*"&B8&"*",Treinamentos_Feitos!$H$2:$H$2000) -> 81042.31 | E8: =IFERROR(D8/C8,0) -> 519.50199
B9: Leonardo da Silva Azevedo | C9: =COUNTIF(Treinamentos_Feitos!$B$2:$B$2000,"*"&B9&"*") -> 269 | D9: =SUMIF(Treinamentos_Feitos!$B$2:$B$2000,"*"&B9&"*",Treinamentos_Feitos!$H$2:$H$2000) -> 135467.41 | E9: =IFERROR(D9/C9,0) -> 503.59632
B10: Roberta de Cássia Martareli | C10: =COUNTIF(Treinamentos_Feitos!$B$2:$B$2000,"*"&B10&"*") -> 204 | D10: =SUMIF(Treinamentos_Feitos!$B$2:$B$2000,"*"&B10&"*",Treinamentos_Feitos!$H$2:$H$2000) -> 101461.01 | E10: =IFERROR(D10/C10,0) -> 497.35789
B11: Lucas Silva dos Santos | C11: =COUNTIF(Treinamentos_Feitos!$B$2:$B$2000,"*"&B11&"*") -> 133 | D11: =SUMIF(Treinamentos_Feitos!$B$2:$B$2000,"*"&B11&"*",Treinamentos_Feitos!$H$2:$H$2000) -> 61758.48 | E11: =IFERROR(D11/C11,0) -> 464.34947
B13: Total geral | C13: =SUM(C5:C11) -> 1015 | D13: =SUM(D5:D11) -> 508824.1
B15: Lojas no pipeline de inauguração (por Status)
B16: Contrato | C16: =COUNTIF(Previsao_Inauguracao!$A$2:$A$1000,B16) -> 25
B17: Descontinuada | C17: =COUNTIF(Previsao_Inauguracao!$A$2:$A$1000,B17) -> 1
B18: Implantação | C18: =COUNTIF(Previsao_Inauguracao!$A$2:$A$1000,B18) -> 11
B19: Negociação | C19: =COUNTIF(Previsao_Inauguracao!$A$2:$A$1000,B19) -> 63
B20: Obra | C20: =COUNTIF(Previsao_Inauguracao!$A$2:$A$1000,B20) -> 35
B21: PNE | C21: =COUNTIF(Previsao_Inauguracao!$A$2:$A$1000,B21) -> 17

Sheet LEIA-ME
B2: Base Unificada — Instrutores AmPm x Rede de Lojas x Treinamentos x Inaugurações
B4: O que este arquivo faz:
B5: Cruza os 4 arquivos enviados numa única base, usando como chave o nome do instrutor
B6: (normalizado e casado por similaridade entre ID_AUVO / ID_CAJU / ID_UBER / nome completo)
B7: e o código PV Abadi para ligar lojas, treinamentos e inaugurações previstas.
B9: Abas:
B10: Instrutores - cadastro único consolidado (ativos e inativos)
B11: Treinamentos_Feitos - histórico de treinamentos já realizados, com instrutor unificado e custo por linha
B12: Rede_de_Lojas - base gerencial completa da rede (1.566 lojas ativas)
B13: Previsao_Inauguracao - pipeline de novas lojas/inaugurações e dias de treinamento necessários
B14: Recomendacao_Deslocamento - para cada loja do pipeline, os 3 instrutores ativos mais próximos
B15: Agenda_Semanal_Sugerida - agenda por instrutor, semana a semana, já roteirizada por proximidade
... B45: de PROXIMIDADE (quem está mais perto), não como custo final em R$.

Sheet Instrutores
A1: instr_id | B1: ID_UNICO | C1: ID_AUVO | D1: ID_CAJU | E1: ID_UBER | F1: NOME_COMPLETO | G1: TELEFONE | H1: EMAIL | I1: ENDERECO | J1: CPF | K1: STATUS | L1: Cidade | M1: UF | N1: Latitude | O1: Longitude
A2: 1 | B2: Betânia Pregnolato | C2: Betânia Pregnolato | D2: Betania Cayret Pregnolato | E2: Betania Cayret Pregnolato | F2: Betânia Cayret Pregnolato | G2: (11) 99351-1743 | H2: betania.ampm@igtgroup-ext.com.br | I2: Rua Manuel da Cunha Azevedo, nº 53, VILA GRANADA , São Paulo - SP // CEP: 03623-050 | J2: 126.130.838-75 | K2: Ativo | L2: São Paulo | M2: SP | N2: -23.5329 | O2: -46.6395
A3: 2 | B3: Bruno Ferreira | C3: Bruno Ferreira | D3: Bruno Ferreira De Souza | E3: Bruno Souza | F3: Bruno Souza | G3: (11) 99596-6401 | H3: bruno.ampm@igtgroup-ext.com.br | I3: RUA MAR VERMELHO,798 JD REGINA ALICE - BARUERI - SP, CEP 06412140 | J3: 360089058/14 | K3: Ativo | L3: Barueri | M3: SP | N3: -23.5057 | O3: -46.879
A4: 3 | B4: Carla Dionizio | C4: Carla Dionizio | D4: Carla Fernandes Dionizio | E4: Carla Fernandes Dionizio | F4: Carla Fernandes Dionizio | G4: (11) 98744-7398 | H4: carla.ampm@igtgroup-ext.com.br | I4: Rua Visconde de Ribamar, 125 A, Jardim Capela, São Paulo - SP // CEP: 04960-100 | J4: 327.521.458-61 | K4: Ativo | L4: São Paulo | M4: SP | N4: -23.5329 | O4: -46.6395
A5: 4 | B5: Isabela Paim | C5: Isabela Paim | D5: Isabela Paim Ricardo | E5: Isabela Paim | F5: Isabela Paim Ricardo | G5: (21) 99390-7088 | H5: isabela.ampm@igtgroup-ext.com.br | I5: Rua Garzon 62 JD LG 1 CA 11 LAGOA | J5: 786.909.007-72 | K5: Ativo | L5: Rio de Janeiro | M5: RJ | N5: -22.9129 | O5: -43.2003
A6: 5 | B6: Leonardo Azevedo | C6: Leonardo Azevedo | D6: Leonardo Da Silva Azevedo | E6: Leonardo Azevedo | F6: Leonardo da Silva Azevedo | G6: (53) 8112-3384 | H6: leonardo.ampm@igtgroup-ext.com.br | I6: Rua Val Porto, 223, Salgado filho, cep 96202-700 - RS | J6: 646.916.400-53 | K6: Ativo | L6: Rio Grande | M6: RS | N6: -32.0349 | O6: -52.1071
A7: 6 | B7: Roberta de Cassia | C7: Roberta de Cassia | D7: Roberta De Cássia Martareli | E7: Roberta de Cássia | F7: Roberta de Cássia Martareli | G7: (11) 95337-4199 | H7: roberta.ampm@igtgroup-ext.com.br | I7: Rua lagoa d'anta 60, pq cisper São Paulo, CEP 03818-030 | J7: 291.322.248-00 | K7: Ativo | L7: São Paulo | M7: SP | N7: -23.5329 | O7: -46.6395
A8: 7 | B8: Lucas Silva | C8: Lucas Silva | D8: Lucas Silva Dos Santos | E8: Lucas Silva | F8: Lucas Silva dos Santos | G8: (11) 97707-5141 | H8: lucas.ampm@igtgroup-ext.com.br | I8: Rua Paraíba, 324, Nossa Senhora de Fátima, Monte Carmelo - MG. CEP: 38500-000 | J8: 095.374.106-09 | K8: Ativo | L8: Monte Carlo | M8: MG
A9: 8 | B9: Andre Luiz | C9: Andre Luiz | D9: AndrÃ© Luiz De Medeiros | E9: Andre Luiz | F9: André Luiz de Medeiros | G9: (81) 9386-9032 | H9: andre.ampm@igtgroup-ext.com.br | I9: R SEBASTIAO DO SOUTO 109, CEP 54360-030 | J9: 034.327.224-51 | K9: Saiu
A10: 9 | B10: Diego Henrique | C10: Diego Henrique | D10: Diego Henrique De Souza | E10: Diego Henrique | F10: Diego Henrique de Souza | G10: (41) 8706-3610 | H10: diego.ampm@igtgroup-ext.com.br | I10: aRua florindo Rinaldin n° 92 sobrado 3, CEP 81810-600 | J10: 066.830.679-37 | K10: Saiu
A11: 10 | B11: Juliano Amoretti | C11: Juliano Amoretti | D11: Juliano Rodrigues Amoretti | F11: Juliano Rodrigues Amoretti | G11: (48) 9138-0057 | H11: juliano.ampm@igtgroup-ext.com.br | I11: Rua Campeche 1560 CEP: 88063-300 | J11: 005.050.010-47 | K11: Saiu
A12: 11 | B12: Marcela Lourenço | C12: Marcela Lourenço | D12: Marcela Lourenço Venegas | E12: Marcela Lourenço | F12: Marcela Lourenço | G12: (43) 9159-2334 | H12: marcela.ampm@igtgroup-ext.com.br | I12: Av Joao Miguel Caram, 1075 - BL2 AP 702 ANDAR 8 | J12: 043.614.499-96 | K12: Saiu
A13: 12 | B13: Simone Franceschi | C13: Simone Franceschi | D13: Simone Franceschi Barreto | E13: Simone Franceshi | F13: Simone Franceschi Barreto | G13: (47) 9252-8844 | H13: simone.ampm@igtgroup-ext.com.br | I13: RUA ARNALDO DAVETT 386 BOA ESPINHEIROS, CEP 89228-560 JOINVILLE - SC | J13: 075.811.997-62 | K13: Saiu
A14: 13 | B14: Tabajara Grecca | C14: Tabajara Grecca | D14: Tabajara Grecca | F14: Tabajara Grecca | G14: (19) 98161-1163 | H14: tabajara.ampm@igtgroup-ext.com.br | I14: Av. José Luis Camargo Moreira, 33 ap 42 torre 2 - Mansões Santo Antonio - Campinas/SP - CEP: 13087-511 | J14: 071520578/18 | K14: Saiu

Sheet Treinamentos_Feitos
A1: Data | B1: Instrutor_Unificado | C1: Posto | D1: PV Abadi | E1: Tipo do Treinamento | F1: ValorAjudadeCusto | G1: ValorDiária | H1: Custo_Total_R$ | I1: Cidade | J1: Reginal | K1: ciclo.competencia
A2: 45467 | B2: André Luiz de Medeiros | C2: 120261 - Auto Posto Estradao De Itarare Ltda | D2: 120261 | E2: teste | F2: 105.47 | G2: 238.1 | H2: 495.23 | I2: Rio de Janeiro - RJ | J2: Sudeste | K2: 01/06/2024
A3: 45470 | B3: André Luiz de Medeiros | C3: Sede Igt | E3: teste | F3: 105.47 | G3: 238.1 | H3: 495.23 | I3: Rio de Janeiro - RJ | J3: Sudeste | K3: 01/06/2024
A4: 45490 | B4: William Nunes (NAO CADASTRADO) | C4: 1275371 - Posto Avant Eireli | D4: 1275371 | E4: Treinamento de Loja Café | F4: 105.47 | G4: 238.1 | H4: 495.23 | I4: Canoas - RS | J4: Sul | K4: 01/07/2024
A5: 45491 | B5: William Nunes (NAO CADASTRADO) | C5: 1275371 - Posto Avant Eireli | D5: 1275371 | E5: Treinamento de Loja Café | F5: 105.47 | G5: 238.1 | H5: 495.23 | I5: Canoas - RS | J5: Sul | K5: 01/07/2024
A6: 45492 | B6: William Nunes (NAO CADASTRADO) | C6: 1275371 - Posto Avant Eireli | D6: 1275371 | E6: Treinamento de Loja Café | F6: 105.47 | G6: 238.1 | H6: 495.23 | I6: Canoas - RS | J6: Sul | K6: 01/07/2024
A7: 45495 | B7: William Nunes (NAO CADASTRADO) | C7: 1334528 - Posto Sao Joaquim Eireli | D7: 1334528 | E7: Treinamento de Loja Padaria | F7: 105.47 | G7: 238.1 | H7: 495.23 | I7: Sao Leopoldo - RS | J7: Sul | K7: 01/07/2024
A8: 45496 | B8: William Nunes (NAO CADASTRADO) | C8: 1334528 - Posto Sao Joaquim Eireli | D8: 1334528 | E8: Treinamento de Loja Padaria | F8: 105.47 | G8: 238.1 | H8: 495.23 | I8: Sao Leopoldo - RS | J8: Sul | K8: 01/07/2024
A9: 45497 | B9: William Nunes (NAO CADASTRADO) | C9: 1334528 - Posto Sao Joaquim Eireli | D9: 1334528 | E9: Treinamento de Loja Padaria | F9: 105.47 | G9: 238.1 | H9: 495.23 | I9: Sao Leopoldo - RS | J9: Sul | K9: 01/07/2024
A10: 45498 | B10: Diego Henrique de Souza | C10: 1300414 - Auto Posto Valencia Ltda | D10: 1300414 | E10: Treinamento de 93Burger | F10: 105.47 | G10: 238.1 | H10: 495.23 | I10: Curitiba - PR | J10: Sul | K10: 01/07/2024
A11: 45498 | B11: Diego Henrique de Souza | C11: 1300414 - Auto Posto Valencia Ltda | D11: 1300414 | E11: Treinamento de 93Burger | F11: 0 | G11: 0 | H11: 0 | I11: Curitiba - PR | J11: Sul | K11: 01/07/2024
A12: 45498 | B12: William Nunes (NAO CADASTRADO) | C12: 1334528 - Posto Sao Joaquim Eireli | D12: 1334528 | E12: Treinamento de Loja Padaria | F12: 105.47 | G12: 238.1 | H12: 495.23 | I12: Sao Leopoldo - RS | J12: Sul | K12: 01/07/2024
A13: 45499 | B13: William Nunes (NAO CADASTRADO) | C13: 1334528 - Posto Sao Joaquim Eireli | D13: 1334528 | E13: Treinamento de Loja Padaria | F13: 105.47 | G13: 238.1 | H13: 495.23 | I13: Sao Leopoldo - RS | J13: Sul | K13: 01/07/2024
A14: 45499 | B14: Simone Franceschi Barreto | C14: 101284 - Patio Contorno Comercio De Combustiveis | D14: 101284 | E14: Treinamento de 93Burger | F14: 105.47 | G14: 0 | H14: 152.02 | I14: Curitiba - PR | J14: Sul | K14: 01/07/2024
A15: 45510 | B15: André Luiz de Medeiros | C15: 1365924 - Posto 4 Rodas Eireli | D15: 1365924 | E15: Treinamento de Loja Café | F15: 105.47 | G15: 238.1 | H15: 495.23 | I15: São Miguel dos Campos - AL | J15: Nordeste | K15: 01/08/2024
... A29: 45518 | B29: Lucas Silva dos Santos | C29: 1305137 - Rede Dol Comercio De Combustiveis Ltda | D29: 1305137 | E29: Treinamento de Loja Café | F29: 105.47 | G29: 238.1 | H29: 495.23 | I29: Uberlândia - MG | J29: Sudeste | K29: 01/08/2024
A30: 45518 | B30: Simone Franceschi Barreto | C30: Treinamento Online | E30: Implantação | F30: 105.47 | G30: 0 | H30: 152.02 | I30: Online | J30: Norte | K30: 01/08/2024
A31: 45518 | B31: Simone Franceschi Barreto | C31: Treinamento Online | E31: Implantação | F31: 0 | G31: 0 | H31: 0 | I31: Online | J31: Norte | K31: 01/08/2024
A32: 45519 | B32: Diego Henrique de Souza | C32: 1305012 - Chr Comercio De Combustiveis Ltda | D32: 1305012 | E32: Treinamento de Loja Padaria | F32: 105.47 | G32: 238.1 | H32: 495.23 | I32: Maringa - PR | J32: Sul | K32: 01/08/2024
A33: 45519 | B33: Lucas Silva dos Santos | C33: 1305137 - Rede Dol Comercio De Combustiveis Ltda | D33: 1305137 | E33: Treinamento de Loja Café | F33: 105.47 | G33: 238.1 | H33: 495.23 | I33: Uberlândia - MG | J33: Sudeste | K33: 01/08/2024
A34: 45519 | B34: Simone Franceschi Barreto | C34: Treinamento Online | E34: Implantação | F34: 105.47 | G34: 0 | H34: 152.02 | I34: Online | J34: Norte | K34: 01/08/2024
A35: 45520 | B35: Simone Franceschi Barreto | C35: Treinamento Online | E35: Implantação | F35: 0 | G35: 0 | H35: 0 | I35: Online | J35: Norte | K35: 01/08/2024
A36: 45520 | B36: Simone Franceschi Barreto | C36: Treinamento Online | E36: Implantação | F36: 0 | G36: 0 | H36: 0 | I36: Online | J36: Norte | K36: 01/08/2024
A37: 45520 | B37: Simone Franceschi Barreto | C37: Treinamento Online | E37: Implantação | F37: 0 | G37: 0 | H37: 0 | I37: Online | J37: Norte | K37: 01/08/2024
A38: 45520 | B38: Simone Franceschi Barreto | C38: Treinamento Online | E38: Implantação | F38: 105.47 | G38: 0 | H38: 152.02 | I38: Online | J38: Norte | K38: 01/08/2024
A39: 45520 | B39: Diego Henrique de Souza | C39: 1305012 - Chr Comercio De Combustiveis Ltda | D39: 1305012 | E39: Treinamento de Loja Padaria | F39: 105.47 | G39: 238.1 | H39: 495.23 | I39: Maringa - PR | J39: Sul | K39: 01/08/2024
A40: 45523 | B40: Simone Franceschi Barreto | C40: Treinamento Online | E40: Treinamento de Loja Padaria | F40: 105.47 | G40: 0 | H40: 152.02 | I40: Curitiba - PR | J40: Sul | K40: 01/08/2024
A41: 45523 | B41: William Nunes (NAO CADASTRADO) | C41: 1275508 - Posto De Combustiveis Caminho Do Gol Lt | D41: 1275508 | E41: Implantação | F41: 105.47 | G41: 238.1 | H41: 495.23 | I41: Taquara - RS | J41: Sul | K41: 01/08/2024
A42: 45524 | B42: Lucas Silva dos Santos | C42: 1335388 - Posto Jardim Veneza Ltda | D42: 1335388 | E42: Implantação | F42: 105.47 | G42: 238.1 | H42: 495.23 | I42: Uberlândia -MG - 10 | J42: Norte | K42: 01/08/2024
A43: 45524 | B43: Simone Franceschi Barreto | C43: Treinamento Online | E43: Treinamento de Loja Padaria | F43: 105.47 | G43: 0 | H43: 152.02 | I43: Curitiba - PR | J43: Sul | K43: 01/08/2024
A44: 45524 | B44: William Nunes (NAO CADASTRADO) | C44: 1275508 - Posto De Combustiveis Caminho Do Gol Lt | D44: 1275508 | E44: Inauguração | F44: 105.47 | G44: 238.1 | H44: 495.23 | I44: Porto Alegre - RS | J44: Sul | K44: 01/08/2024
A45: 45525 | B45: Lucas Silva dos Santos | C45: 1304905 - Ursa Maior Derivados De Petroleo Ltda | D45: 1304905 | E45: Implantação | F45: 105.47 | G45: 238.1 | H45: 495.23 | I45: Uberlândia - MG | J45: Sudeste | K45: 01/08/2024
A46: 45525 | B46: Lucas Silva dos Santos | C46: 1304905 - Ursa Maior Derivados De Petroleo Ltda | D46: 1304905 | E46: Implantação | F46: 0 | G46: 0 | H46: 0 | I46: Uberlandia - MG | J46: Sudeste | K46: 01/08/2024
A47: 45525 | B47: Simone Franceschi Barreto | C47: Treinamento Online | E47: Treinamento de Loja Padaria | F47: 105.47 | G47: 0 | H47: 152.02 | I47: Curitiba - PR | J47: Sul | K47: 01/08/2024
A48: 45525 | B48: William Nunes (NAO CADASTRADO) | C48: 1275508 - Posto De Combustiveis Caminho Do Gol Lt | D48: 1275508 | E48: Inauguração | F48: 105.47 | G48: 238.1 | H48: 495.23 | I48: Porto Alegre - RS | J48: Sul | K48: 01/08/2024
A49: 45526 | B49: William Nunes (NAO CADASTRADO) | C49: 1275508 - Posto De Combustiveis Caminho Do Gol Lt | D49: 1275508 | E49: Inauguração | F49: 105.47 | G49: 238.1 | H49: 495.23 | I49: Porto Alegre - RS | J49: Sul | K49: 01/08/2024
A50: 45526 | B50: Simone Franceschi Barreto | C50: Treinamento Online | E50: Treinamento de Loja Padaria | F50: 105.47 | G50: 0 | H50: 152.02 | I50: Curitiba - PR | J50: Sul | K50: 01/08/2024
A51: 45526 | B51: Lucas Silva dos Santos | C51: 1348992 - Auto Posto Morada Ltda | D51: 1348992 | E51: Implantação | F51: 0 | G51: 0 | H51: 0 | I51: Uberaba - MG | J51: Sudeste | K51: 01/08/2024
A52: 45526 | B52: Lucas Silva dos Santos | C52: 1404999 - Rede Super S 2.0 Ltda | D52: 1404999 | E52: Implantação | F52: 105.47 | G52: 238.1 | H52: 495.23 | I52: Uberaba - MG | J52: Sudeste | K52: 01/08/2024
A53: 45527 | B53: Lucas Silva dos Santos | C53: 1372737 - Abastecedora Fenix Ltda | D53: 1372737 | E53: Implantação | F53: 105.47 | G53: 238.1 | H53: 495.23 | I53: Uberaba - MG | J53: Sudeste | K53: 01/08/2024
...

Sheet Rede_de_Lojas
A1: PV Abadi | B1: Razão Social | C1: Status Loja | D1: Municipio | E1: UF | F1: Endereço | G1: CEP | H1: Data Inauguracao | I1: Modelo Loja Gerencial | J1: GF | K1: CF | L1: Latitude | M1: Longitude
A2: 404622 | B2: Jl Lemos Combustivel Ltda | C2: Ativo | D2: Jaboatao Dos Guararapes | E2: PE | F2: Av Ayrton Senna Da Silva 3300 | G2: 54410240 | H2: 44124 | I2: Ampm Padaria Compacta 2020 | J2: GF N/NE | K2: Caroline De Figueiredo Cavalcanti Albuquerque | L2: -8.11298 | M2: -35.015
A3: 613879 | B3: Auto Posto Ferrari Ltda | C3: Ativo | D3: Porto Alegre | E3: RS | F3: Av Juca Batista 4329 | G3: 91755000 | H3: 38376 | I3: Loja Ampm 2020 | J3: GF RS | K3: Karine Silveira Boardmann | L3: -30.0318 | M3: -51.2065
A4: 4230 | B4: C A Olimpia Bandeirantes Ltda | C4: Ativo | D4: Sao Paulo | E4: SP | F4: R Bugio, 79 | G4: 4548070 | H4: 35551 | I4: Ampm Padaria Compacta Fachada 2025 | J4: GF SP Capital | K4: Peterson Da Silva Conceicao | L4: -23.5329 | M4: -46.6395
A5: 613886 | B5: Abastecedora De Combustiveis Neiva Ltda | C5: Ativo | D5: Porto Alegre | E5: RS | F5: Av Wenceslau Escobar 2226 | G5: 91900000 | H5: 45139 | I5: Ampm Padaria Compacta 2020 | J5: GF RS | K5: Karine Silveira Boardmann | L5: -30.0318 | M5: -51.2065
A6: 12632 | B6: Jli Combustivel Ltda | C6: Ativo | D6: Jaboatao Dos Guararapes | E6: PE | F6: R Aniceto Varejao 530 | G6: 54420310 | H6: 43056 | I6: Ampm Padaria Compacta 2020 | J6: GF N/NE | K6: Caroline De Figueiredo Cavalcanti Albuquerque | L6: -8.11298 | M6: -35.015
A7: 619761 | B7: Gdo Participacoes S/A | C7: Ativo | D7: Sao Paulo | E7: SP | F7: Av Dos Bandeirantes 3686 | G7: 4071000 | H7: 37165 | I7: Ampm Padaria Compacta 2020 | J7: GF SP Capital | K7: Flavio Pereira De Almeida | L7: -23.5329 | M7: -46.6395
A8: 4194 | B8: Posto Uni Icaray Ltda | C8: Ativo | D8: Aracatuba | E8: SP | F8: Av Joaquim Pompeu De Toledo 1631 | G8: 16020105 | H8: 35643 | I8: Loja Ampm | J8: GF SP Interior | K8: Thais Viana Silva | L8: -21.2076 | M8: -50.4401
A9: 620584 | B9: Posto Uni Paulistinha Ltda | C9: Ativo | D9: Presidente Prudente | E9: SP | F9: Av Washington Luiz 1067 | G9: 19015150 | H9: 42706 | I9: Ampm Padaria Compacta 2025 | J9: GF SP Interior | K9: Thais Viana Silva | L9: -22.1207 | M9: -51.3925
A10: 621129 | B10: Edilma De Oli Lac Siqueira Campos Me | C10: Ativo | D10: Sertania | E10: PE | F10: Av Cicero Lacerda 48 | G10: 56600000 | H10: 40908 | I10: Loja Ampm Fachada 2020 | J10: GF N/NE | K10: Caroline De Figueiredo Cavalcanti Albuquerque | L10: -8.06847 | M10: -37.2684
A11: 11095 | B11: Dist Way De Combs Ltda | C11: Ativo | D11: Rio De Janeiro | E11: RJ | F11: Av Das Americas 2100 | G11: 22640101 | H11: 38169 | I11: Ampm Padaria Full 2020 | J11: GF Sudeste | K11: Andre Luiz Nogueira Mantuano | L11: -22.9129 | M11: -43.2003
A12: 621267 | B12: Posto Monteiro Ltda | C12: Ativo | D12: Cabo De Santo Agostinho | E12: PE | F12: Rod Pe 60 Sn Km 08 | G12: 54520992 | H12: 41313 | I12: Loja Ampm 2025 | J12: GF N/NE | K12: Caroline De Figueiredo Cavalcanti Albuquerque | L12: -8.28218 | M12: -35.0253
A13: 13252 | B13: Posto Barra Linda Ltda | C13: Ativo | D13: Rio De Janeiro | E13: RJ | F13: Av Das Americas 7000 | G13: 22793081 | H13: 35827 | I13: Ampm Padaria Full Fachada 2020 | J13: GF Sudeste | K13: Andre Luiz Nogueira Mantuano | L13: -22.9129 | M13: -43.2003
... A222: 22231 | B222: Auto Posto Casil Ltda | C222: Ativo | D222: Sao Jose Dos Pinhais | E222: PR | F222: R Tenente Djalma Dutra 125 | G222: 83005360 | H222: 36130 | I222: Ampm Padaria Full 2025 | J222: GF PR | K222: Jheniffer Guimaraes Catafesta | L222: -25.5313 | M222: -49.2031
A223: 2959 | B223: Cruzada Da Barra Padaria Ltda | C223: Ativo | D223: Rio De Janeiro | E223: RJ | F223: Av Das Americas 3201 Lt 1 Qd 1 | H223: 34121 | I223: Ampm Padaria Full 2020 | J223: GF Sudeste | K223: Andre Luiz Nogueira Mantuano | L223: -22.9129 | M223: -43.2003
A224: 22386 | B224: Posto Barra Norte Ltda | C224: Ativo | D224: Balneario Camboriu | E224: SC | F224: Av Brasil, 220 | G224: 88330040 | H224: 35462 | I224: Ampm Padaria Full | J224: GF SC | K224: Hallmes Dos Santos Oliveira | L224: -26.9926 | M224: -48.6352
A225: 401031 | B225: P De Serv Dengoso Ltda | C225: Ativo | D225: Rio De Janeiro | E225: RJ | F225: Est Do Monteiro, 50 | G225: 23045830 | H225: 41513 | I225: Loja Ampm | J225: GF Sudeste | K225: Andre Luiz Nogueira Mantuano | L225: -22.9129 | M225: -43.2003
A226: 22531 | B226: A P Prudente - Portico Ltda | C226: Ativo | D226: Joinville | E226: SC | F226: R 15 De Novembro 4380 | G226: 89216202 | H226: 35977 | I226: Loja Ampm | J226: GF SC | K226: Tais Da Costa Albano | L226: -26.3045 | M226: -48.8487
A227: 10336 | B227: Via Gas Posto De Servicos Ltda | C227: Ativo | D227: Itaborai | E227: RJ | F227: Av 22 De Maio Sn Lote 01 Quadra 88 | G227: 24800001 | H227: 42675 | I227: Loja Ampm Fachada 2025 | J227: GF Sudeste | K227: Andre Luiz Nogueira Mantuano | L227: -22.7565 | M227: -42.8639
A228: 22629 | B228: Auto Posto Afonso Pena Ltda | C228: Ativo | D228: Curitiba | E228: PR | F228: R Treze De Maio 260 | G228: 80020270 | H228: 44862 | I228: Ampm Padaria Compacta 2025 | J228: GF PR | K228: Jheniffer Guimaraes Catafesta | L228: -25.4195 | M228: -49.2646
A229: 406999 | B229: P Rio Dos Meros Ltda | C229: Ativo | D229: Paraty | E229: RJ | F229: Av Roberto Silveira Sn Qd B Lt 1 | G229: 23970000 | H229: 45649 | I229: Ampm Padaria Compacta Fachada 2025 | J229: GF Sudeste | K229: Andre Luiz Nogueira Mantuano | L229: -23.2221 | M229: -44.7175
A230: 22725 | B230: Auto Posto Principal Ltda | C230: Ativo | D230: Araucaria | E230: PR | F230: Av Doutor Victor Do Amaral 1080 | G230: 83702040 | H230: 38261 | I230: Ampm Padaria Compacta Fachada 2025 | J230: GF PR | K230: Nathalie Voigt | L230: -25.5859 | M230: -49.4047
A231: 23405 | B231: Posto Jotaka Comercio De Combs Ltda | C231: Ativo | D231: Maringa | E231: PR | F231: Av Sao Paulo 2471 Loja 01 | G231: 87005040 | H231: 35827 | I231: Ampm Padaria Compacta 2020 | J231: GF PR | K231: Diego Henrique De Souza | L231: -23.4205 | M231: -51.9333
A232: 402112 | B232: Auto Posto Esal Ltda | C232: Ativo | D232: Angra Dos Reis | E232: RJ | F232: R Almte Machado Portella 179 | G232: 23906190 | H232: 45638 | I232: Ampm Padaria Full 2025 | J232: GF Sudeste | K232: Andre Luiz Nogueira Mantuano | L232: -23.0011 | M232: -44.3196
A233: 23417 | B233: A P Ortona Ltda | C233: Ativo | D233: Curitiba | E233: PR | F233: R Alberto Folloni 1181 | G233: 80540000 | H233: 43829 | I233: Loja Ampm 2025 | J233: GF PR | K233: Wilds Willians Ozanski Campos | L233: -25.4195 | M233: -49.2646
A234: 102066 | B234: Distribuidora Penna Ltda | C234: Ativo | D234: Uberlandia | E234: MG | F234: Av Comendador Alexandrino Garcia 1175 | G234: 38402228 | H234: 36831 | I234: Loja Ampm 2025 | J234: GF Sudeste | K234: Antoniele Meneses Sa | L234: -18.9141 | M234: -48.2749
A235: 14564 | B235: Conveniencia Petroleum Ltda | C235: Ativo | D235: Sao Jose Do Rio Preto | E235: SP | F235: Av Bady Bassitt 4154 | G235: 15025000 | H235: 36161 | I235: Ampm Padaria Full 2020 | J235: GF SP Interior | K235: Bianca Garcia Panchame Da Silveira | L235: -20.8113 | M235: -49.3758
... A292: 613651 | B292: Posto Linha Verde Ltda | C292: Ativo | D292: Viamao | E292: RS | F292: Av Senador Salgado Filho 7277 | G292: 94435000 | H292: 35103 | I292: Ampm Padaria Full 2025 | J292: GF RS | K292: Karine Silveira Boardmann | L292: -30.0819 | M292: -51.0194
A293: 613743 | B293: Abastecedora De Combustiveis Rotula 030 | C293: Ativo | E293: RS | H293: 46203 | I293: Loja Ampm | J293: GF RS | K293: Deborah Evelyn Oliveira
A294: 613884 | B294: Shopping Coml Abast Pr Pet C S Ltda | C294: Ativo | D294: Porto Alegre | E294: RS | F294: Av Joao Wallig 1903 | G294: 91340001 | H294: 35886 | I294: Ampm Padaria Compacta 2020 | J294: GF RS | K294: Marcelo De Abreu Sager | L294: -30.0318 | M294: -51.2065
A295: 620249 | B295: Expresso Conveniencia Lanchonete & Merc | C295: Ativo | D295: Uberaba | E295: MG | F295: Av Nene Sabino 1167 | G295: 38055500 | H295: 44711 | I295: Loja Ampm 2020 | J295: GF Sudeste | K295: Antoniele Meneses Sa | L295: -19.7472 | M295: -47.9381
A296: 613847 | B296: Gbi Combustiveis Ltda | C296: Ativo | D296: Rio Grande | E296: RS | F296: R General Neto 555 | G296: 96200010 | H296: 45461 | I296: Ampm Padaria Compacta 2020 | J296: GF RS | K296: Ruann Goulart Tadiello | L296: -32.0349 | M296: -52.1071
A297: 632730 | B297: Expres Conveni Lanch & Merc Joao Naves | C297: Ativo | D297: Uberlandia | E297: MG | F297: Av Joao Naves De Avila 2735 | G297: 38408144 | H297: 44795 | I297: Loja Ampm 2020 | J297: GF Sudeste | K297: Antoniele Meneses Sa | L297: -18.9141 | M297: -48.2749
A298: 613683 | B298: Auto Posto Felipao Ltda | C298: Ativo | D298: Santa Maria | E298: RS | F298: Av Angelo Bolsson 846 | G298: 97070000 | H298: 36130 | I298: Loja Ampm 2025 | J298: GF RS | K298: Filipe Almeida Candido Da Silva | L298: -29.6868 | M298: -53.8149
A299: 613754 | B299: Mp Postos E Logistica Ltda | C299: Ativo | D299: Santa Maria | E299: RS | F299: Av Presidente Vargas 1079 | G299: 97015511 | H299: 35916 | I299: Loja Ampm | J299: GF RS | K299: Filipe Almeida Candido Da Silva | L299: -29.6868 | M299: -53.8149
A300: 601535 | B300: Posto Linha Verde Ltda | C300: Ativo | D300: Porto Alegre | E300: RS | F300: Av Farrapos 858 | G300: 90220000 | H300: 45513 | I300: Ampm Padaria Compacta Fachada 2025 | J300: GF RS | K300: Karine Silveira Boardmann | L300: -30.0318 | M300: -51.2065
A301: 613958 | B301: Rede Furnas Com Combs Ltda | C301: Ativo | D301: Sombrio | E301: SC | F301: Rod Br 101 1320 Km 437 Cxpostal 44 | G301: 88960000 | H301: 37404 | I301: Ampm Padaria Compacta 2025 | J301: GF SC | K301: Simone Franceschi Barreto | L301: -29.108 | M301: -49.6328
A302: 621317 | B302: Charpinel Rocha Conveniencias Ltda | C302: Ativo | D302: Alegre | E302: ES | F302: R Monsenhor Pavesi 153 | G302: 29500000 | H302: 45654 | I302: Loja Ampm 2020 | J302: GF Sudeste | K302: Eduardo Furtado Goncalves | L302: -20.758 | M302: -41.5382
A303: 45876 | B303: Posto Do Guerra Com Combs Ltda | C303: Ativo | D303: Carlos Barbosa | E303: RS | F303: R Buarque De Macedo 3931 | G303: 95185000 | H303: 36161 | I303: Loja Ampm Fachada 2025 | J303: GF RS | K303: Deborah Evelyn Oliveira | L303: -29.2969 | M303: -51.5028
A304: 45946 | B304: Abastecedora De Combustiveis Karen Ltda | C304: Ativo | D304: Porto Alegre | E304: RS | F304: Av Otto Niemeyer 2265 | G304: 91910180 | H304: 43718 | I304: Ampm Padaria Compacta | J304: GF RS | K304: Karine Silveira Boardmann | L304: -30.0318 | M304: -51.2065
...

Sheet Previsao_Inauguracao
A1: Status | B1: PV ABADI | C1: Razão Social | D1: Gerência de Franquia | E1: Consultor de Franquia | F1: Consultor_Possivel_Instrutor | G1: Previsão Inauguração | H1: UF | I1: Município | J1: Pipeline | K1: Modelo de Loja | L1: Dias de Treinamento | M1: Latitude | N1: Longitude
A2: Negociação | B2: 4008 | C2: Posto Novo Batel Ltda | D2: GF PR | E2: Nathalie Voigt | G2: 01/06/2026 | H2: PR | I2: Curitiba | J2: Pizza Hut | K2: Padaria | L2: 5 | M2: -25.4195 | N2: -49.2646
A3: Implantação | B3: 3136 | C3: Auto Posto Aventador Ltda | D3: GF PR | E3: Jheniffer Guimaraes Catafesta | G3: 01/06/2026 | H3: PR | I3: Curitiba | J3: Pizza Hut | K3: Padaria | L3: 5 | M3: -25.4195 | N3: -49.2646
A4: Negociação | B4: 670164 | C4: Centro Automotivo Blue Machine Ltda | D4: GF SP Capital | E4: Lucas Ramos Dos Santos | G4: 01/06/2026 | H4: SP | I4: Sao Paulo | J4: Pizza Hut | K4: Padaria | L4: 5 | M4: -23.5329 | N4: -46.6395
A5: Negociação | B5: 2633 | C5: Auto Posto Petrosolo Ltda | D5: GF PR | E5: Marcela Venegas | F5: Marcela Lourenço | G5: 01/06/2026 | H5: PR | I5: Londrina | J5: Pizza Hut | K5: Padaria | L5: 5 | M5: -23.304 | N5: -51.1691
A6: Negociação | B6: 615250 | C6: Longhi Rede De Varejo Ltda. | D6: GF RS | E6: Deborah Evelyn Oliveira | G6: 01/06/2026 | H6: RS | I6: Caxias Do Sul | J6: Pizza Hut | K6: Padaria | L6: 5 | M6: -29.1629 | N6: -51.1792
A7: Negociação | B7: 607663 | C7: H Lang Filho Comercio Representacoes E | D7: GF RS | E7: Ruann Goulart Tadiello | G7: 01/06/2026 | H7: RS | I7: Pelotas | J7: Pizza Hut | K7: Café | L7: 3 | M7: -31.7649 | N7: -52.3371
A8: Negociação | B8: 614469 | C8: Fauri Comercio De Combustiveis Ltda | D8: GF RS | E8: Marcelo De Abreu Sager | G8: 01/06/2026 | H8: RS | I8: Porto Alegre | J8: Pizza Hut | K8: Padaria | L8: 5 | M8: -30.0318 | N8: -51.2065
A9: Negociação | B9: 616571 | C9: Garagem Belem Ltda | D9: GF RS | E9: Mariana Da Costa Dale | G9: 01/06/2026 | H9: RS | I9: Porto Alegre | J9: Pizza Hut | K9: Café | L9: 3 | M9: -30.0318 | N9: -51.2065
A10: Negociação | B10: 23405 | C10: Posto Jotaka Comercio De Combs Ltda | D10: GF PR | E10: Diego Henrique De Souza | F10: Diego Henrique de Souza | G10: 01/06/2026 | H10: PR | I10: Maringa | J10: Pizza Hut | K10: Padaria | L10: 5 | M10: -23.4205 | N10: -51.9333
A11: Implantação | B11: 404887 | C11: Champagnat Conveniencia Ltda | D11: GF Sudeste | E11: Eduardo Furtado Goncalves | G11: 01/06/2026 | H11: ES | I11: Vila Velha | J11: Pizza Hut | K11: Padaria | L11: 5 | M11: -20.3417 | N11: -40.2875
A12: Negociação | B12: 631557 | C12: Posto De Combustiveis Dal Ri Ltda. | D12: GF RS | E12: Filipe Almeida Candido Da Silva | G12: 01/06/2026 | H12: RS | I12: Santa Maria | J12: Pizza Hut | K12: Café | L12: 3 | M12: -29.6868 | N12: -53.8149
A13: Negociação | B13: 614155 | C13: Com Maqs Combs Pitangueira Ltda | D13: GF RS | E13: Filipe Almeida Candido Da Silva | G13: 01/06/2026 | H13: RS | I13: Itaqui | J13: Pizza Hut | K13: Padaria | L13: 5 | M13: -29.1311 | N13: -56.5515
A14: Negociação | B14: 601535 | C14: Posto Linha Verde Ltda | D14: GF RS | E14: Karine Silveira Boardmann | G14: 01/06/2026 | H14: RS | I14: Porto Alegre | J14: Pizza Hut | K14: Padaria | L14: 5 | M14: -30.0318 | N14: -51.2065
A15: Implantação | B15: 613958 | C15: Rede Furnas Com Combs Ltda | D15: GF SC | E15: Simone Franceschi Barreto | F15: Simone Franceschi Barreto | G15: 01/06/2026 | H15: SC | I15: Sombrio | J15: Pizza Hut | K15: Padaria | L15: 5 | M15: -29.108 | N15: -49.6328
A16: Negociação | B16: 615552 | C16: Combustiveis Pegasus Ipiranga Ltda | D16: GF RS | E16: Marcelo De Abreu Sager | G16: 01/06/2026 | H16: RS | I16: Porto Alegre | J16: Pizza Hut | K16: Padaria | L16: 5 | M16: -30.0318 | N16: -51.2065
A17: Negociação | B17: 604138 | C17: Abastecedora De Combustiveis Rioxel Ltd | D17: GF RS | E17: Diana Cristina Kahmann | G17: 01/06/2026 | H17: RS | I17: Guaiba | J17: Pizza Hut | K17: Café | L17: 3 | M17: -30.1086 | N17: -51.3233
A18: Implantação | B18: 617994 | C18: Auto Posto Almirante Ltda | D18: GF RS | E18: Karine Silveira Boardmann | G18: 01/06/2026 | H18: RS | I18: Porto Alegre | J18: Pizza Hut | K18: Padaria | L18: 5 | M18: -30.0318 | N18: -51.2065
A19: Implantação | B19: 670597 | C19: Conveniencia Av4 Eireli - Me | D19: GF SP Interior | E19: Leniele Demarque Rossi | G19: 01/06/2026 | H19: SP | I19: Fernandopolis | J19: Pizza Hut | K19: Café | L19: 3 | M19: -20.2806 | N19: -50.2471
A20: Negociação | B20: 614078 | C20: Jp Santa Lucia Comercio De Combustiveis | D20: GF RS | E20: Filipe Almeida Candido Da Silva | G20: 01/06/2026 | H20: RS | I20: Sao Borja | J20: Pizza Hut | K20: Padaria | L20: 5 | M20: -28.6578 | N20: -56.0036
A21: Negociação | B21: 42378 | C21: Sander Comercio De Combustiveis Ltda | D21: GF RS | E21: Deborah Evelyn Oliveira | G21: 01/06/2026 | H21: RS | I21: Caxias Do Sul | J21: Pizza Hut | K21: Café | L21: 3 | M21: -29.1629 | N21: -51.1792
A22: Negociação | B22: 22604 | C22: Fernanda Raquel Lenz Ravanello - Epp | D22: GF PR | E22: Nathalie Voigt | G22: 01/06/2026 | H22: PR | I22: Uniao Da Vitoria | J22: Pizza Hut | K22: Café | L22: 3 | M22: -26.2273 | N22: -51.0873
A23: Negociação | B23: 603597 | C23: Auto Posto Aguia Do Ibirapuera Ltda. | D23: GF SP Capital | E23: Lucas Ramos Dos Santos | G23: 01/06/2026 | H23: SP | I23: Sao Paulo | J23: Pizza Hut | K23: Café | L23: 3 | M23: -23.5329 | N23: -46.6395
A24: Negociação | B24: 616573 | C24: Posto Rede Salvaro 36 Ltda | D24: GF RS | E24: Mariana Da Costa Dale | G24: 01/06/2026 | H24: RS | I24: Novo Hamburgo | J24: Pizza Hut | K24: Café | L24: 3 | M24: -29.6875 | N24: -51.1328
A25: Negociação | B25: 614828 | C25: Posto Linha Verde Ltda | D25: GF RS | E25: Karine Silveira Boardmann | G25: 01/06/2026 | H25: RS | I25: Porto Alegre | J25: Pizza Hut | K25: Padaria | L25: 5 | M25: -30.0318 | N25: -51.2065
A26: Implantação | B26: 625456 | C26: Auto Posto Alfa Ltda | D26: GF PR | E26: Wilds Willians Ozanski Campos | G26: 01/06/2026 | H26: PR | I26: Colombo | J26: Pizza Hut | K26: Café | L26: 3 | M26: -25.2925 | N26: -49.2262
A27: Negociação | B27: 21379 | C27: Auto Posto Salvaro Ii Ltda | D27: GF PR | E27: Mariangela Galvan Silveira | G27: 01/06/2026 | H27: PR | I27: Guarapuava | J27: Pizza Hut | K27: Café | L27: 3 | M27: -25.3902 | N27: -51.4623
... A40: Obra | B40: 36195 | C40: POSTO DE SERVICOS PROFISSIONALISMO LTDA | D40: GF SP Capital | E40: Jessica Passos | G40: 30/06/2026 | H40: SP | I40: Sao Paulo | J40: Implantação | K40: Box Adaptado | L40: 1 | M40: -23.5329 | N40: -46.6395
A41: Obra | B41: 679889 | C41: POSTO IMPERIO DE GUAPI - Antecipado | D41: GF Sudeste | E41: Isabela Leal | G41: 30/06/2026 | H41: RJ | I41: - | J41: Implantação | K41: Box Adaptado | L41: 1
A42: Obra | B42: 610561 | C42: SUPORTE COM DE COMBS E SERVICOS LTDA - Antcipado | D42: GF SP Interior | E42: Leniele Demarque Rossi | G42: 30/06/2026 | H42: SP | I42: Catanduva | J42: Implantação | K42: Box Adaptado | L42: 1 | M42: -21.1314 | N42: -48.977
A43: Obra | B43: 735063 | C43: AUTO POSTO MASTER | D43: GF SP Interior | E43: Thais Viana Silva | G43: 30/06/2026 | H43: SP | I43: Marilia | J43: Implantação | K43: Café | L43: 3 | M43: -22.2171 | N43: -49.9501
A44: Obra | B44: 16332 | C44: POSTO SAO CRISTOVAO DE MARILIA - Antecipado | D44: GF SP Interior | E44: Thais Viana Silva | G44: 30/06/2026 | H44: SP | I44: Marilia | J44: Implantação | K44: Café | L44: 3 | M44: -22.2171 | N44: -49.9501
A45: Obra | B45: 18009 | C45: AUTO POSTO PRIMALE - Antecipado | D45: GF SP Capital | E45: Lyvia Mesquita | G45: 30/06/2026 | H45: SP | I45: Sao Paulo | J45: Implantação | K45: Café | L45: 3 | M45: -23.5329 | N45: -46.6395
A46: Obra | B46: 638235 | C46: AUTO POSTO PÉROLA PRATA LTDA | D46: GF SP Capital | E46: Flavio Almeida | G46: 30/06/2026 | H46: SP | I46: Barueri | J46: Implantação | K46: Box Adaptado | L46: 1 | M46: -23.5057 | N46: -46.879
A47: Negociação | B47: 5251 | C47: A P Capital Ltda | D47: GF PR | E47: Jheniffer Guimaraes Catafesta | G47: 01/07/2026 | H47: PR | I47: Curitiba | J47: Pizza Hut | K47: Padaria | L47: 5 | M47: -25.4195 | N47: -49.2646
A48: Negociação | B48: 3337 | C48: Auto Posto Bca Luiziana Ltda | D48: GF PR | E48: Diego Henrique De Souza | F48: Diego Henrique de Souza | G48: 01/07/2026 | H48: PR | I48: Maringa | J48: Pizza Hut | K48: Padaria | L48: 5 | M48: -23.4205 | N48: -51.9333
A49: Negociação | B49: 3907 | C49: P De Abast E Serv V Marques Ltda | D49: GF Sudeste | E49: Emanuel Francisco Pena | G49: 01/07/2026 | H49: RJ | I49: Rio De Janeiro | J49: Pizza Hut | K49: Padaria | L49: 5 | M49: -22.9129 | N49: -43.2003
A50: Negociação | B50: 18450 | C50: Auto Posto Alvorada Ii Ltda | D50: GF SP Capital | E50: Lyvia Martins Mesquita | G50: 01/07/2026 | H50: SP | I50: Sao Paulo | J50: Pizza Hut | K50: Café | L50: 3 | M50: -23.5329 | N50: -46.6395
A51: Negociação | B51: 621066 | C51: Fabiane Uarte Carvalho Ludtke Ltda | D51: GF RS | E51: Ruann Goulart Tadiello | G51: 01/07/2026 | H51: RS | I51: Turucu | J51: Pizza Hut | K51: Padaria | L51: 5 | M51: -31.4173 | N51: -52.1706
A52: Implantação | B52: 23578 | C52: Rede Furnas Comercio De Combustiveis | D52: GF SC | E52: Simone Franceschi Barreto | F52: Simone Franceschi Barreto | G52: 01/07/2026 | H52: SC | I52: Tubarao | J52: Pizza Hut | K52: Padaria | L52: 5 | M52: -28.4713 | N52: -49.0144
...

Sheet Recomendacao_Deslocamento
A1: PV_ABADI | B1: Razao_Social | C1: Municipio_Loja | D1: UF_Loja | E1: Previsao_Inauguracao | F1: Dias_Treinamento_Necessarios | G1: Ranking_Proximidade | H1: Instrutor_Sugerido | I1: Cidade_Instrutor | J1: UF_Instrutor | K1: Distancia_km_linha_reta
A2: 4008 | B2: Posto Novo Batel Ltda | C2: Curitiba | D2: PR | E2: 01/06/2026 | F2: 5 | G2: 1 | H2: Bruno Souza | I2: Barueri | J2: SP | K2: 321.8
A3: 4008 | B3: Posto Novo Batel Ltda | C3: Curitiba | D3: PR | E3: 01/06/2026 | F3: 5 | G3: 2 | H3: Betânia Cayret Pregnolato | I3: São Paulo | J3: SP | K3: 338.5
A4: 4008 | B4: Posto Novo Batel Ltda | C4: Curitiba | D4: PR | E4: 01/06/2026 | F4: 5 | G4: 3 | H4: Carla Fernandes Dionizio | I4: São Paulo | J4: SP | K4: 338.5
A5: 3136 | B5: Auto Posto Aventador Ltda | C5: Curitiba | D5: PR | E5: 01/06/2026 | F5: 5 | G5: 1 | H5: Bruno Souza | I5: Barueri | J5: SP | K5: 321.8
A6: 3136 | B6: Auto Posto Aventador Ltda | C6: Curitiba | D6: PR | E6: 01/06/2026 | F6: 5 | G6: 2 | H6: Betânia Cayret Pregnolato | I6: São Paulo | J6: SP | K6: 338.5
A7: 3136 | B7: Auto Posto Aventador Ltda | C7: Curitiba | D7: PR | E7: 01/06/2026 | F7: 5 | G7: 3 | H7: Carla Fernandes Dionizio | I7: São Paulo | J7: SP | K7: 338.5
A8: 670164 | B8: Centro Automotivo Blue Machine Ltda | C8: Sao Paulo | D8: SP | E8: 01/06/2026 | F8: 5 | G8: 1 | H8: Betânia Cayret Pregnolato | I8: São Paulo | J8: SP | K8: 0
A9: 670164 | B9: Centro Automotivo Blue Machine Ltda | C9: Sao Paulo | D9: SP | E9: 01/06/2026 | F9: 5 | G9: 2 | H9: Carla Fernandes Dionizio | I9: São Paulo | J9: SP | K9: 0
A10: 670164 | B10: Centro Automotivo Blue Machine Ltda | C10: Sao Paulo | D10: SP | E10: 01/06/2026 | F10: 5 | G10: 3 | H10: Roberta de Cássia Martareli | I10: São Paulo | J10: SP | K10: 0
A11: 2633 | B11: Auto Posto Petrosolo Ltda | C11: Londrina | D11: PR | E11: 01/06/2026 | F11: 5 | G11: 1 | H11: Bruno Souza | I11: Barueri | J11: SP | K11: 438.3
A12: 2633 | B12: Auto Posto Petrosolo Ltda | C12: Londrina | D12: PR | E12: 01/06/2026 | F12: 5 | G12: 2 | H12: Betânia Cayret Pregnolato | I12: São Paulo | J12: SP | K12: 462.9
A13: 2633 | B13: Auto Posto Petrosolo Ltda | C13: Londrina | D13: PR | E13: 01/06/2026 | F13: 5 | G13: 3 | H13: Carla Fernandes Dionizio | I13: São Paulo | J13: SP | K13: 462.9
... A412: 652619 | B412: Posto Guajara Ltda | C412: Capanema | D412: PA | E412: 30/12/2026 | F412: 1 | G412: 3 | H412: Betânia Cayret Pregnolato | I412: São Paulo | J412: SP | K412: 2483.4

Sheet Agenda_Semanal_Sugerida
A1: Instrutor | B1: Semana_Num | C1: Periodo | D1: Ordem_na_Rota | E1: PV_Abadi | F1: Loja | G1: Municipio | H1: UF | I1: Tipo_Necessidade | J1: Dias_Treinamento | K1: Distancia_desde_ponto_anterior_km
A2: Betânia Cayret Pregnolato | B2: 1 | C2: 03/08/2026 a 07/08/2026 | D2: 1 | E2: 14065 | F2: A P Serra De Braganca Ltda | G2: Sao Paulo | H2: SP | I2: Retreinamento | J2: 2 | K2: 0
A3: Betânia Cayret Pregnolato | B3: 1 | C3: 03/08/2026 a 07/08/2026 | D3: 2 | E3: 658759 | F3: Novo Modena Auto Posto Ltda | G3: Sao Paulo | H3: SP | I3: Retreinamento | J3: 2 | K3: 0
A4: Betânia Cayret Pregnolato | B4: 2 | C4: 10/08/2026 a 14/08/2026 | D4: 1 | E4: 719865 | F4: Grupo Majore Paula Auto Posto Ltda | G4: Sao Paulo | H4: SP | I4: Retreinamento | J4: 2 | K4: 0
A5: Betânia Cayret Pregnolato | B5: 2 | C5: 10/08/2026 a 14/08/2026 | D5: 2 | E5: 1142 | F5: Auto Posto Leao De Pirituba Ltda | G5: Sao Paulo | H5: SP | I5: Retreinamento | J5: 2 | K5: 0
A6: Betânia Cayret Pregnolato | B6: 3 | C6: 17/08/2026 a 21/08/2026 | D6: 1 | E6: 660537 | F6: Fast Giant Da Engenheiro Ltda | G6: Sao Paulo | H6: SP | I6: Retreinamento | J6: 2 | K6: 0
A7: Betânia Cayret Pregnolato | B7: 3 | C7: 17/08/2026 a 21/08/2026 | D7: 2 | E7: 678596 | F7: Centro Automotivo Himalaia Ltda | G7: Sao Paulo | H7: SP | I7: Retreinamento | J7: 2 | K7: 0
A8: Betânia Cayret Pregnolato | B8: 4 | C8: 24/08/2026 a 28/08/2026 | D8: 1 | E8: 705591 | F8: Auto Posto Rede Ban 2 Ltda | G8: Sao Paulo | H8: SP | I8: Retreinamento | J8: 2 | K8: 0
A9: Betânia Cayret Pregnolato | B9: 4 | C9: 24/08/2026 a 28/08/2026 | D9: 2 | E9: 621742 | F9: Sigmar Conveniencias Ltda | G9: Sao Paulo | H9: SP | I9: Retreinamento | J9: 2 | K9: 0
A10: Betânia Cayret Pregnolato | B10: 5 | C10: 31/08/2026 a 04/09/2026 | D10: 1 | E10: 670164 | F10: Centro Automotivo Blue Machine Ltda | G10: Sao Paulo | H10: SP | I10: Treinamento Nova Loja (Pizza Hut) | J10: 5 | K10: 0
A11: Betânia Cayret Pregnolato | B11: 6 | C11: 07/09/2026 a 11/09/2026 | D11: 1 | E11: 718591 | F11: Loja De Conveniencia Brothers Birmann L | G11: Sao Paulo | H11: SP | I11: Treinamento Nova Loja (Pizza Hut) | J11: 3 | K11: 0
A12: Betânia Cayret Pregnolato | B12: 7 | C12: 14/09/2026 a 18/09/2026 | D12: 1 | E12: 723622 | F12: AUTO POSTO MIGLIANO LTDA | G12: Sao Paulo | H12: SP | I12: Treinamento Nova Loja (Implantação) | J12: 3 | K12: 0
A13: Betânia Cayret Pregnolato | B13: 8 | C13: 21/09/2026 a 25/09/2026 | D13: 1 | E13: 18450 | F13: Auto Posto Alvorada Ii Ltda | G13: Sao Paulo | H13: SP | I13: Treinamento Nova Loja (Pizza Hut) | J13: 3 | K13: 0
... A372: Roberta de Cássia Martareli | B372: 37 | C372: 12/04/2027 a 16/04/2027 | D372: 1 | E372: 648819 | F372: Auto Posto Independencia Com.Combs.Serv | G372: Belem | H372: PA | I372: Retreinamento | J372: 2 | K372: 2463

Sheet Fila_CallCenter
A1: PV_Abadi | B1: Loja | C1: Municipio | D1: UF | E1: Tipo_Necessidade | F1: Data_Ultimo_Treinamento | G1: Dias_desde_Ultimo_Treinamento | H1: Instrutor_Sugerido | I1: Semana_Sugerida | J1: Telefone_Contato | K1: Status_Contato | L1: Data_do_Contato | M1: Observacoes
A2: 621193 | B2: Conveniencia Rodrigues E Companhia Ltda | C2: Atalaia | D2: AL | E2: Retreinamento | F2: 45786 | G2: 448 | H2: Isabela Paim Ricardo | I2: 19/04/2027 a 23/04/2027 | K2: A Contatar
A3: 621258 | B3: New Star Com De Combs E Lubrifi Ltda | C3: Maceio | D3: AL | E3: Retreinamento | F3: 45643 | G3: 591 | H3: Isabela Paim Ricardo | I3: 05/04/2027 a 09/04/2027 | K3: A Contatar
A4: 621112 | B4: Auto Posto Bariloche Eireli | C4: Maceio | D4: AL | E4: Retreinamento | F4: 45644 | G4: 590 | H4: Isabela Paim Ricardo | I4: 05/04/2027 a 09/04/2027 | K4: A Contatar
A5: 709048 | B5: Beluma Comercio De Combustiveis Ltda | C5: Maceio | D5: AL | E5: Retreinamento | F5: 45777 | G5: 457 | H5: Isabela Paim Ricardo | I5: 12/04/2027 a 16/04/2027 | K5: A Contatar
A6: 665493 | B6: Pratagy Frances Ltda | C6: Marechal Deodoro | D6: AL | E6: Retreinamento | F6: 45783 | G6: 451 | H6: Carla Fernandes Dionizio | I6: 22/03/2027 a 26/03/2027 | K6: A Contatar
A7: 724183 | B7: POSTO SANTA RITA | C7: Rio Largo | D7: AL | E7: Treinamento Nova Loja (Implantação) | H7: Isabela Paim Ricardo | I7: 12/04/2027 a 16/04/2027 | K7: A Contatar
A8: 702900 | B8: TULEMON COMERCIO | C8: Rio Largo | D8: AL | E8: Treinamento Nova Loja (Implantação) | H8: Isabela Paim Ricardo | I8: 19/04/2027 a 23/04/2027 | K8: A Contatar
A9: 654251 | B9: POSTO ALEXA LTDA | C9: Sao Sebastiao | D9: AL | E9: Treinamento Nova Loja (Implantação) | H9: Isabela Paim Ricardo | I9: 15/03/2027 a 19/03/2027 | K9: A Contatar
A10: 646306 | B10: Auto Posto Sabalanga Ltda - Me | C10: Vicosa | D10: AL | E10: Retreinamento | F10: 45849 | G10: 385 | H10: Carla Fernandes Dionizio | I10: 22/03/2027 a 26/03/2027 | K10: A Contatar
A11: 684108 | B11: Mucuripe Varejo Ltda | C11: Manaus | D11: AM | E11: Retreinamento | F11: 45694 | G11: 540 | H11: Carla Fernandes Dionizio | I11: 05/04/2027 a 09/04/2027 | K11: A Contatar
A12: 731313 | B12: MUCURIPE COMERCIO DE COMBS | C12: Manaus | D12: AM | E12: Treinamento Nova Loja (Implantação) | H12: Betânia Cayret Pregnolato | I12: 12/04/2027 a 16/04/2027 | K12: A Contatar
A13: 30141 | B13: Conveniencia Mts Ltda | C13: Salvador | D13: BA | E13: Retreinamento | F13: 45632 | G13: 602 | H13: Roberta de Cássia Martareli | I13: 05/04/2027 a 09/04/2027 | K13: A Contatar
A14: 620305 | B14: Maisbarato - Comercio De Alimentos Ltda | C14: Brasilia | D14: DF | E14: Retreinamento | F14: 45859 | G14: 375 | H14: Isabela Paim Ricardo | I14: 15/03/2027 a 19/03/2027 | K14: A Contatar
A15: 620436 | B15: Maisbarato - Comercio De Alimentos Ltda | C15: Brasilia | D15: DF | E15: Retreinamento | F15: 45861 | G15: 373 | H15: Bruno Souza | I15: 22/03/2027 a 26/03/2027 | K15: A Contatar
A16: 620371 | B16: Loja De Conveniencia Candanga Ltda | C16: Brasilia | D16: DF | E16: Retreinamento | F16: 45568 | G16: 666 | H16: Betânia Cayret Pregnolato | I16: 25/01/2027 a 29/01/2027 | K16: A Contatar
A17: 701821 | B17: Texas Conveniencia Ltda Me | C17: Cariacica | D17: ES | E17: Treinamento Nova Loja (Pizza Hut) | H17: Isabela Paim Ricardo | I17: 14/12/2026 a 18/12/2026 | K17: A Contatar
A18: 701882 | B18: Auto Posto Aldeia Da Praia Ltda | C18: Guarapari | D18: ES | E18: Treinamento Nova Loja (Pizza Hut) | H18: Isabela Paim Ricardo | I18: 30/11/2026 a 04/12/2026 | K18: A Contatar
A19: 621320 | B19: AUTO POSTO ROTA 66 LTDA | C19: Guarapari | D19: ES | E19: Treinamento Nova Loja (Implantação) | H19: Isabela Paim Ricardo | I19: 07/12/2026 a 11/12/2026 | K19: A Contatar
A20: 621412 | B20: Marataizes Conveniencia Ltda | C20: Marataizes | D20: ES | E20: Retreinamento | F20: 45569 | G20: 665 | H20: Isabela Paim Ricardo | I20: 26/10/2026 a 30/10/2026 | K20: A Contatar
A21: 621293 | B21: Auto Posto Paulo Layber Ltda | C21: Piuma | D21: ES | E21: Retreinamento | F21: 45583 | G21: 651 | H21: Isabela Paim Ricardo | I21: 26/10/2026 a 30/10/2026 | K21: A Contatar
A22: 646174 | B22: POSTO ALEGRE LTDA | C22: Sooretama | D22: ES | E22: Treinamento Nova Loja (Implantação) | H22: Isabela Paim Ricardo | I22: 04/01/2027 a 08/01/2027 | K22: A Contatar
A23: 717245 | B23: POSTO VILA LTDA | C23: VARGEM ALTA | D23: ES | E23: Treinamento Nova Loja (Implantação) | H23: Isabela Paim Ricardo | I23: 09/11/2026 a 13/11/2026 | K23: A Contatar
A24: 404887 | B24: Champagnat Conveniencia Ltda | C24: Vila Velha | D24: ES | E24: Treinamento Nova Loja (Pizza Hut) | H24: Isabela Paim Ricardo | I24: 21/12/2026 a 25/12/2026 | K24: A Contatar
A25: 621479 | B25: Convento Conveniencia Ltda | C25: Vitoria | D25: ES | E25: Treinamento Nova Loja (Pizza Hut) | H25: Isabela Paim Ricardo | I25: 28/12/2026 a 01/01/2027 | K25: A Contatar
A26: 12773 | B26: Santa Rita Comercio De Combs Ltda | C26: Vitoria | D26: ES | E26: Treinamento Nova Loja (Pizza Hut) | H26: Isabela Paim Ricardo | I26: 04/01/2027 a 08/01/2027 | K26: A Contatar
A27: 703352 | B27: Antonelli & Vitorino Comercio De Combus | C27: Abadiania | D27: GO | E27: Treinamento Nova Loja (Implantação) | H27: Betânia Cayret Pregnolato | I27: 15/03/2027 a 19/03/2027 | K27: A Contatar
A28: 637488 | B28: CAMBUI COM DE DERIV DE PETROLEO LTDA | C28: Aparecida De Goiania | D28: GO | E28: Treinamento Nova Loja (Implantação) | H28: Betânia Cayret Pregnolato | I28: 08/03/2027 a 12/03/2027 | K28: A Contatar
A29: 687318 | B29: Conveniencia Global Arena Ltda | C29: Goiania | D29: GO | E29: Retreinamento | F29: 45812 | G29: 422 | H29: Carla Fernandes Dionizio | I29: 22/02/2027 a 26/02/2027 | K29: A Contatar
A30: 643183 | B30: Passeio Das Aguas Conveniencia Ltda | C30: Goiania | D30: GO | E30: Retreinamento | F30: 45825 | G30: 409 | H30: Roberta de Cássia Martareli | I30: 15/03/2027 a 19/03/2027 | K30: A Contatar
A31: 620409 | B31: Ferreira Matias Combustiveis I Ltda | C31: Goiania | D31: GO | E31: Retreinamento | F31: 45587 | G31: 647 | H31: Carla Fernandes Dionizio | I31: 28/12/2026 a 01/01/2027 | K31: A Contatar
A32: 620373 | B32: POSTO JARDIM BOTANICO LTDA | C32: Goiania | D32: GO | E32: Treinamento Nova Loja (Implantação) | H32: Bruno Souza | I32: 15/02/2027 a 19/02/2027 | K32: A Contatar
A33: 643184 | B33: AUTO POSTO CASCAVEL LTDA | C33: Goiania | D33: GO | E33: Treinamento Nova Loja (Implantação) | H33: Isabela Paim Ricardo | I33: 18/01/2027 a 22/01/2027 | K33: A Contatar
A34: 636489 | B34: L S Comercio E Servicos Ltda | C34: Sao Luis | D34: MA | E34: Retreinamento | F34: 45804 | G34: 430 | H34: Carla Fernandes Dionizio | I34: 29/03/2027 a 02/04/2027 | K34: A Contatar
A35: 623932 | B35: AGUIAR PETROLEO E LOCACOES LTDA | C35: Sao Luis | D35: MA | E35: Treinamento Nova Loja (Implantação) | H35: Carla Fernandes Dionizio | I35: 29/03/2027 a 02/04/2027 | K35: A Contatar
A36: 7737 | B36: Raja Nobre Loja De Conveniencia Ltda | C36: Belo Horizonte | D36: MG | E36: Retreinamento | F36: 45590 | G36: 644 | H36: Betânia Cayret Pregnolato | I36: 30/11/2026 a 04/12/2026 | K36: A Contatar
A37: 613443 | B37: Conveniencia Nossa Senhora D Bom Despac | C37: Belo Horizonte | D37: MG | E37: Retreinamento | F37: 45807 | G37: 427 | H37: Betânia Cayret Pregnolato | I37: 28/12/2026 a 01/01/2027 | K37: A Contatar
A38: 651045 | B38: Conv.Nossa Senhora Do Bom Despacho Ltda | C38: Betim | D38: MG | E38: Retreinamento | F38: 45806 | G38: 428 | H38: Roberta de Cássia Martareli | I38: 01/02/2027 a 05/02/2027 | K38: A Contatar
A39: 32148 | B39: Capital Conveniencias E Servicos Ltda | C39: Contagem | D39: MG | E39: Retreinamento | F39: 45748 | G39: 486 | H39: Betânia Cayret Pregnolato | I39: 28/12/2026 a 01/01/2027 | K39: A Contatar
A40: 32295 | B40: POSTO ALTO PARANAIBA EIRELI | C40: Monte Carmelo | D40: MG | E40: Treinamento Nova Loja (Implantação) | H40: Carla Fernandes Dionizio | I40: 28/12/2026 a 01/01/2027 | K40: A Contatar
...

Sheet Qualidade_dos_Dados
A1: Categoria | B1: Detalhe | C1: Impacto
A2: Instrutor não cadastrado | B2: William Nunes aparece em 30 treinamentos no histórico mas não existe no cadastro 2026_AMPM-instrutores.xlsx | C2: Custos e histórico dele ficam fora dos totais por instrutor
A3: Cidade não geocodificada | B3: Instrutor: Lucas Silva dos Santos — cidade 'monte carlo' UF informada 'MG': Cidade existe no IBGE apenas em: SC (confira se a UF do cadastro esta certa) | C3: Não entra no cálculo de distância/proximidade
A4: Cidade não geocodificada | B4: Previsao PV 679889.0 — cidade '' UF informada 'RJ': Cidade nao encontrada na base IBGE (nome pode estar diferente/abreviado) | C4: Não entra no cálculo de distância/proximidade
A5: Cidade não geocodificada | B5: Previsao PV 40954.0 — cidade '' UF informada '-': Cidade nao encontrada na base IBGE (nome pode estar diferente/abreviado) | C5: Não entra no cálculo de distância/proximidade
A6: Cidade não geocodificada | B6: Previsao PV 664984.0 — cidade '' UF informada 'MT': Cidade nao encontrada na base IBGE (nome pode estar diferente/abreviado) | C6: Não entra no cálculo de distância/proximidade
A7: Cidade não geocodificada | B7: Previsao PV 999999455.0 — cidade '' UF informada '-': Cidade nao encontrada na base IBGE (nome pode estar diferente/abreviado) | C7: Não entra no cálculo de distância/proximidade
A8: Cidade não geocodificada | B8: Previsao PV 100050.0 — cidade '' UF informada 'SP ': Cidade nao encontrada na base IBGE (nome pode estar diferente/abreviado) | C8: Não entra no cálculo de distância/proximidade
A9: Cidade não geocodificada | B9: Previsao PV 42249.0 — cidade '' UF informada '-': Cidade nao encontrada na base IBGE (nome pode estar diferente/abreviado) | C9: Não entra no cálculo de distância/proximidade
A10: Cidade não geocodificada | B10: Previsao PV 16372.0 — cidade '' UF informada '-': Cidade nao encontrada na base IBGE (nome pode estar diferente/abreviado) | C10: Não entra no cálculo de distância/proximidade
A11: Cidade não geocodificada | B11: Previsao PV 632227.0 — cidade '' UF informada 'SC': Cidade nao encontrada na base IBGE (nome pode estar diferente/abreviado) | C11: Não entra no cálculo de distância/proximidade
A12: Cidade não geocodificada | B12: Previsao PV 635097.0 — cidade '' UF informada '-': Cidade nao encontrada na base IBGE (nome pode estar diferente/abreviado) | C12: Não entra no cálculo de distância/proximidade
... A45: Cobertura do histórico | B45: 1.186 das 1.566 lojas ativas não têm NENHUM registro no histórico de treinamentos enviado — não foram tratadas como "atrasadas" porque provavelmente o histórico enviado não cobre a vida toda da loja, só cobrem um recorte (jun/2024 a jul/2026) | C45: Se a intenção for testar TODA a rede e não só quem já treinou antes, essa lista de 1.186 precisa ser revisada com a área de operações
